### Common Error Handling Operators in Combine

1. **`catch`**

   - The `catch` operator intercepts errors from an upstream publisher and allows you to replace the error with another publisher, effectively recovering from the error.

   **Example:**

   ```swift
   import Combine
   
   let failingPublisher = Fail<Int, Error>(error: URLError(.badServerResponse))
   
   let recoveredPublisher = failingPublisher
       .catch { error in
           Just(0) // Return a default value on error
       }
       .sink { value in
           print("Received value: \(value)")
       }
   
   // Output: Received value: 0
   ```

   In this example, when the `failingPublisher` emits an error, the `catch` operator catches it and replaces it with a publisher that emits a default value (`0` in this case).

2. **`replaceError`**

   - The `replaceError` operator replaces any error emitted by the upstream publisher with a provided default value.

   **Example:**

   ```swift
   import Combine
   
   let failingPublisher = Fail<Int, Error>(error: URLError(.badServerResponse))
   
   let replacedPublisher = failingPublisher
       .replaceError(with: 42) // Replace error with a default value
       .sink { value in
           print("Received value: \(value)")
       }
   
   // Output: Received value: 42
   ```

   Here, instead of handling the error in a custom way, `replaceError` simply replaces any error with a given value.

3. **`tryMap`**

   - The `tryMap` operator is a variant of the `map` operator that allows throwing errors within the transformation closure. If an error is thrown, it propagates down the stream, and you can handle it with other operators like `catch`.

   **Example:**

   ```swift
   import Combine
   
   let numbers = [1, 2, 3, 4].publisher
   
   let mappedPublisher = numbers
       .tryMap { number -> Int in
           if number == 3 {
               throw URLError(.badServerResponse)
           }
           return number * 2
       }
       .catch { _ in Just(0) } // Replace error with a default value
       .sink { value in
           print("Received value: \(value)")
       }
   
   // Output: 2, 4, 0
   ```

   In this case, `tryMap` throws an error when it encounters the number `3`, and `catch` handles it by replacing the error with a default value (`0`).

4. **`mapError`**

   - The `mapError` operator allows you to transform an error into another error, which can be useful for converting errors to a different type or providing more context.

   **Example:**

   ```swift
   import Combine
   
   let failingPublisher = Fail<Int, URLError>(error: URLError(.badServerResponse))
   
   let mappedErrorPublisher = failingPublisher
       .mapError { error in
           return MyCustomError.networkError(error) // Convert to custom error type
       }
       .sink(
           receiveCompletion: { completion in
               if case let .failure(error) = completion {
                   print("Received error: \(error)")
               }
           },
           receiveValue: { value in
               print("Received value: \(value)")
           }
       )
   
   enum MyCustomError: Error {
       case networkError(URLError)
   }
   
   // Output: Received error: networkError(URLError)
   ```

   Here, `mapError` converts a `URLError` into a custom `MyCustomError` type, allowing more flexible error handling downstream.

### Error Handling in SwiftUI Views

When integrating Combine publishers into SwiftUI views, you often handle errors by displaying alerts or fallback UI. Here's an example of how you might handle errors in a SwiftUI view:

```swift
import SwiftUI
import Combine

struct ContentView: View {
    @State private var data: String = ""
    @State private var showError: Bool = false
    @State private var errorMessage: String = ""

    var body: some View {
        VStack {
            Text(data.isEmpty ? "Loading..." : data)
                .padding()
        }
        .onAppear {
            fetchData()
        }
        .alert(isPresented: $showError) {
            Alert(title: Text("Error"), message: Text(errorMessage), dismissButton: .default(Text("OK")))
        }
    }

    func fetchData() {
        let url = URL(string: "https://jsonplaceholder.typicode.com/posts/1")!

        URLSession.shared.dataTaskPublisher(for: url)
            .map(\.data)
            .decode(type: Post.self, decoder: JSONDecoder())
            .map { $0.title }
            .replaceError(with: "Failed to load data")
            .receive(on: DispatchQueue.main)
            .sink { result in
                if result == "Failed to load data" {
                    self.errorMessage = result
                    self.showError = true
                } else {
                    self.data = result
                }
            }
            .cancel() // Cancel the subscription when the view disappears
    }
}

struct Post: Codable {
    let title: String
}
```

In this example, a simple `ContentView` attempts to load data from a network request. If an error occurs, the `replaceError` operator provides a fallback message, which triggers an alert in the UI.

### Summary:

- **`catch`**: Recovers from an error by providing another publisher.
- **`replaceError`**: Replaces an error with a default value.
- **`tryMap`**: Allows throwing errors in a transformation and requires handling downstream.
- **`mapError`**: Transforms an error into another error type for better contextual handling.

These operators are key to managing errors effectively in SwiftUI applications that use Combine for handling asynchronous tasks.